Workbook
Name DueSoonDays: 'HR Operations Dashboard'!$B$5
Name EmployeeIDs: tblEmployees[Employee ID]
Name lstDepartment: Lists!$A$2:$A$9
Name lstDocType: Lists!$G$2:$G$5
Name lstEmpStatus: Lists!$C$2:$C$4
Name lstLocation: Lists!$B$2:$B$4
Name lstOwner: Lists!$D$2:$D$5
Name lstSubmission: Lists!$H$2:$H$3
Name lstTask: Lists!$F$2:$F$9
Name lstTaskStatus: Lists!$E$2:$E$4
Name lstVerification: Lists!$I$2:$I$4
Name ReportDate: 'HR Operations Dashboard'!$B$4

Sheet Employee Master
A1: Employee ID | B1: Employee Name | C1: Department | D1: Job Title | E1: Joining Date | F1: Reporting Manager | G1: Work Location | H1: Employment Status
A2: WBS-1007 | B2: Aishwarya Lokhande | C2: Sales | D2: Sales Manager | E2: 43535 | F2: Isha Mehta | G2: Mumbai | H2: Active
A3: WBS-1048 | B3: Ajinkya Jadhav | C3: Marketing | D3: Graphic Designer | E3: 46307 | F3: Deepak More | G3: Mumbai | H3: Onboarding
A4: WBS-1008 | B4: Akash Chavan | C4: Information Technology | D4: IT Manager | E4: 43696 | F4: Isha Mehta | G4: Pune | H4: Active
A5: WBS-1040 | B5: Amey Joshi | C5: Finance | D5: Senior Accountant | E5: 46293 | F5: Kedar Menon | G5: Pune | H5: Onboarding
A6: WBS-1042 | B6: Apeksha Bansal | C6: Operations | D6: Operations Executive | E6: 46296 | F6: Saurabh Patil | G6: Nashik | H6: Active
A7: WBS-1016 | B7: Archana Mane | C7: Human Resources | D7: Recruitment Coordinator | E7: 44575 | F7: Madhuri Jadhav | G7: Pune | H7: Active
A8: WBS-1028 | B8: Bhavna Chaudhari | C8: Operations | D8: Back Office Executive | E8: 46190 | F8: Neha Wagh | G8: Pune | H8: Active
A9: WBS-1010 | B9: Deepak More | C9: Marketing | D9: Marketing Manager | E9: 43864 | F9: Isha Mehta | G9: Mumbai | H9: Active
A10: WBS-1009 | B10: Dhruv Mehta | C10: Finance | D10: Accounts Executive | E10: 43789 | F10: Kedar Menon | G10: Pune | H10: Active
A11: WBS-1050 | B11: Dipti Mane | C11: Customer Support | D11: Senior Support Executive | E11: 46309 | F11: Smita Pillai | G11: Pune | H11: Onboarding
A12: WBS-1015 | B12: Divya Iyer | C12: Information Technology | D12: QA Analyst | E12: 44550 | F12: Akash Chavan | G12: Pune | H12: Notice Period
A13: WBS-1029 | B13: Gaurav Shetty | C13: Marketing | D13: Digital Marketing Executive | E13: 46230 | F13: Deepak More | G13: Pune | H13: Active
... A51: WBS-1025 | B51: Yash Parikh | C51: Customer Support | D51: Quality Analyst | E51: 45866 | F51: Nandini Naik | G51: Pune | H51: Active

Sheet Onboarding Tracker
A1: Task ID | B1: Employee ID | C1: Employee Name | D1: Department | E1: Onboarding Task | F1: Task Owner | G1: Due Date | H1: Completion Date | I1: Status | J1: Overdue | K1: Days Overdue | L1: Due Soon | M1: Remarks
A2: OB-001 | B2: WBS-1033 | C2: =IFERROR(INDEX(tblEmployees[Employee Name],MATCH(tblOnboarding[[#This Row],[Employee ID]],tblEmployees[Employee ID],0)),"ID not found") -> Siddharth Agarwal | D2: =IFERROR(INDEX(tblEmployees[Department],MATCH(tblOnboarding[[#This Row],[Employee ID]],tblEmployees[Employee ID],0)),"") -> Information Technology | E2: Offer letter acknowledgement | F2: HR | G2: 46273 | H2: 46279 | I2: Completed | J2: =IF(OR(tblOnboarding[[#This Row],[Status]]="Completed",tblOnboarding[[#This Row],[Due Date]]=""),"No",IF(tblOnboarding[[#This Row],[Due Date]]<ReportDate,"Yes","No")) -> No | K2: =IF(tblOnboarding[[#This Row],[Overdue]]="Yes",ReportDate-tblOnboarding[[#This Row],[Due Date]],"") | L2: =IF(OR(tblOnboarding[[#This Row],[Status]]="Completed",tblOnboarding[[#This Row],[Due Date]]=""),"No",IF(AND(tblOnboarding[[#This Row],[Due Date]]>=ReportDate,tblOnboarding[[#This Row],[Due Date]]<=ReportDate+DueSoonDays),"Yes","No")) -> No | M2: Delayed - employee on leave
A3: OB-002 | B3: WBS-1033 | C3: =IFERROR(INDEX(tblEmployees[Employee Name],MATCH(tblOnboarding[[#This Row],[Employee ID]],tblEmployees[Employee ID],0)),"ID not found") -> Siddharth Agarwal | D3: =IFERROR(INDEX(tblEmployees[Department],MATCH(tblOnboarding[[#This Row],[Employee ID]],tblEmployees[Employee ID],0)),"") -> Information Technology | E3: Identity document submission | F3: HR | G3: 46274 | H3: 46274 | I3: Completed | J3: =IF(OR(tblOnboarding[[#This Row],[Status]]="Completed",tblOnboarding[[#This Row],[Due Date]]=""),"No",IF(tblOnboarding[[#This Row],[Due Date]]<ReportDate,"Yes","No")) -> No | K3: =IF(tblOnboarding[[#This Row],[Overdue]]="Yes",ReportDate-tblOnboarding[[#This Row],[Due Date]],"") | L3: =IF(OR(tblOnboarding[[#This Row],[Status]]="Completed",tblOnboarding[[#This Row],[Due Date]]=""),"No",IF(AND(tblOnboarding[[#This Row],[Due Date]]>=ReportDate,tblOnboarding[[#This Row],[Due Date]]<=ReportDate+DueSoonDays),"Yes","No")) -> No
A4: OB-003 | B4: WBS-1033 | C4: =IFERROR(INDEX(tblEmployees[Employee Name],MATCH(tblOnboarding[[#This Row],[Employee ID]],tblEmployees[Employee ID],0)),"ID not found") -> Siddharth Agarwal | D4: =IFERROR(INDEX(tblEmployees[Department],MATCH(tblOnboarding[[#This Row],[Employee ID]],tblEmployees[Employee ID],0)),"") -> Information Technology | E4: IT account creation | F4: IT | G4: 46273 | H4: 46279 | I4: Completed | J4: =IF(OR(tblOnboarding[[#This Row],[Status]]="Completed",tblOnboarding[[#This Row],[Due Date]]=""),"No",IF(tblOnboarding[[#This Row],[Due Date]]<ReportDate,"Yes","No")) -> No | K4: =IF(tblOnboarding[[#This Row],[Overdue]]="Yes",ReportDate-tblOnboarding[[#This Row],[Due Date]],"") | L4: =IF(OR(tblOnboarding[[#This Row],[Status]]="Completed",tblOnboarding[[#This Row],[Due Date]]=""),"No",IF(AND(tblOnboarding[[#This Row],[Due Date]]>=ReportDate,tblOnboarding[[#This Row],[Due Date]]<=ReportDate+DueSoonDays),"Yes","No")) -> No
A5: OB-004 | B5: WBS-1033 | C5: =IFERROR(INDEX(tblEmployees[Employee Name],MATCH(tblOnboarding[[#This Row],[Employee ID]],tblEmployees[Employee ID],0)),"ID not found") -> Siddharth Agarwal | D5: =IFERROR(INDEX(tblEmployees[Department],MATCH(tblOnboarding[[#This Row],[Employee ID]],tblEmployees[Employee ID],0)),"") -> Information Technology | E5: Company policy acknowledgement | F5: HR | G5: 46275 | H5: 46275 | I5: Completed | J5: =IF(OR(tblOnboarding[[#This Row],[Status]]="Completed",tblOnboarding[[#This Row],[Due Date]]=""),"No",IF(tblOnboarding[[#This Row],[Due Date]]<ReportDate,"Yes","No")) -> No | K5: =IF(tblOnboarding[[#This Row],[Overdue]]="Yes",ReportDate-tblOnboarding[[#This Row],[Due Date]],"") | L5: =IF(OR(tblOnboarding[[#This Row],[Status]]="Completed",tblOnboarding[[#This Row],[Due Date]]=""),"No",IF(AND(tblOnboarding[[#This Row],[Due Date]]>=ReportDate,tblOnboarding[[#This Row],[Due Date]]<=ReportDate+DueSoonDays),"Yes","No")) -> No
A6: OB-005 | B6: WBS-1033 | C6: =IFERROR(INDEX(tblEmployees[Employee Name],MATCH(tblOnboarding[[#This Row],[Employee ID]],tblEmployees[Employee ID],0)),"ID not found") -> Siddharth Agarwal | D6: =IFERROR(INDEX(tblEmployees[Department],MATCH(tblOnboarding[[#This Row],[Employee ID]],tblEmployees[Employee ID],0)),"") -> Information Technology | E6: HR orientation | F6: HR | G6: 46274 | H6: 46275 | I6: Completed | J6: =IF(OR(tblOnboarding[[#This Row],[Status]]="Completed",tblOnboarding[[#This Row],[Due Date]]=""),"No",IF(tblOnboarding[[#This Row],[Due Date]]<ReportDate,"Yes","No")) -> No | K6: =IF(tblOnboarding[[#This Row],[Overdue]]="Yes",ReportDate-tblOnboarding[[#This Row],[Due Date]],"") | L6: =IF(OR(tblOnboarding[[#This Row],[Status]]="Completed",tblOnboarding[[#This Row],[Due Date]]=""),"No",IF(AND(tblOnboarding[[#This Row],[Due Date]]>=ReportDate,tblOnboarding[[#This Row],[Due Date]]<=ReportDate+DueSoonDays),"Yes","No")) -> No
A7: OB-006 | B7: WBS-1033 | C7: =IFERROR(INDEX(tblEmployees[Employee Name],MATCH(tblOnboarding[[#This Row],[Employee ID]],tblEmployees[Employee ID],0)),"ID not found") -> Siddharth Agarwal | D7: =IFERROR(INDEX(tblEmployees[Department],MATCH(tblOnboarding[[#This Row],[Employee ID]],tblEmployees[Employee ID],0)),"") -> Information Technology | E7: Bank details submission | F7: Payroll | G7: 46279 | H7: 46282 | I7: Completed | J7: =IF(OR(tblOnboarding[[#This Row],[Status]]="Completed",tblOnboarding[[#This Row],[Due Date]]=""),"No",IF(tblOnboarding[[#This Row],[Due Date]]<ReportDate,"Yes","No")) -> No | K7: =IF(tblOnboarding[[#This Row],[Overdue]]="Yes",ReportDate-tblOnboarding[[#This Row],[Due Date]],"") | L7: =IF(OR(tblOnboarding[[#This Row],[Status]]="Completed",tblOnboarding[[#This Row],[Due Date]]=""),"No",IF(AND(tblOnboarding[[#This Row],[Due Date]]>=ReportDate,tblOnboarding[[#This Row],[Due Date]]<=ReportDate+DueSoonDays),"Yes","No")) -> No
A8: OB-007 | B8: WBS-1033 | C8: =IFERROR(INDEX(tblEmployees[Employee Name],MATCH(tblOnboarding[[#This Row],[Employee ID]],tblEmployees[Employee ID],0)),"ID not found") -> Siddharth Agarwal | D8: =IFERROR(INDEX(tblEmployees[Department],MATCH(tblOnboarding[[#This Row],[Employee ID]],tblEmployees[Employee ID],0)),"") -> Information Technology | E8: Department induction | F8: Reporting Manager | G8: 46279 | H8: 46282 | I8: Completed | J8: =IF(OR(tblOnboarding[[#This Row],[Status]]="Completed",tblOnboarding[[#This Row],[Due Date]]=""),"No",IF(tblOnboarding[[#This Row],[Due Date]]<ReportDate,"Yes","No")) -> No | K8: =IF(tblOnboarding[[#This Row],[Overdue]]="Yes",ReportDate-tblOnboarding[[#This Row],[Due Date]],"") | L8: =IF(OR(tblOnboarding[[#This Row],[Status]]="Completed",tblOnboarding[[#This Row],[Due Date]]=""),"No",IF(AND(tblOnboarding[[#This Row],[Due Date]]>=ReportDate,tblOnboarding[[#This Row],[Due Date]]<=ReportDate+DueSoonDays),"Yes","No")) -> No
A9: OB-008 | B9: WBS-1033 | C9: =IFERROR(INDEX(tblEmployees[Employee Name],MATCH(tblOnboarding[[#This Row],[Employee ID]],tblEmployees[Employee ID],0)),"ID not found") -> Siddharth Agarwal | D9: =IFERROR(INDEX(tblEmployees[Department],MATCH(tblOnboarding[[#This Row],[Employee ID]],tblEmployees[Employee ID],0)),"") -> Information Technology | E9: Education certificate verification | F9: HR | G9: 46286 | I9: In Progress | J9: =IF(OR(tblOnboarding[[#This Row],[Status]]="Completed",tblOnboarding[[#This Row],[Due Date]]=""),"No",IF(tblOnboarding[[#This Row],[Due Date]]<ReportDate,"Yes","No")) -> Yes | K9: =IF(tblOnboarding[[#This Row],[Overdue]]="Yes",ReportDate-tblOnboarding[[#This Row],[Due Date]],"") -> 25 | L9: =IF(OR(tblOnboarding[[#This Row],[Status]]="Completed",tblOnboarding[[#This Row],[Due Date]]=""),"No",IF(AND(tblOnboarding[[#This Row],[Due Date]]>=ReportDate,tblOnboarding[[#This Row],[Due Date]]<=ReportDate+DueSoonDays),"Yes","No")) -> No | M9: Sent to verification agency on 09-Oct; report awaited
A10: OB-009 | B10: WBS-1034 | C10: =IFERROR(INDEX(tblEmployees[Employee Name],MATCH(tblOnboarding[[#This Row],[Employee ID]],tblEmployees[Employee ID],0)),"ID not found") -> Karan Pawar | D10: =IFERROR(INDEX(tblEmployees[Department],MATCH(tblOnboarding[[#This Row],[Employee ID]],tblEmployees[Employee ID],0)),"") -> Sales | E10: Offer letter acknowledgement | F10: HR | G10: 46274 | H10: 46274 | I10: Completed | J10: =IF(OR(tblOnboarding[[#This Row],[Status]]="Completed",tblOnboarding[[#This Row],[Due Date]]=""),"No",IF(tblOnboarding[[#This Row],[Due Date]]<ReportDate,"Yes","No")) -> No | K10: =IF(tblOnboarding[[#This Row],[Overdue]]="Yes",ReportDate-tblOnboarding[[#This Row],[Due Date]],"") | L10: =IF(OR(tblOnboarding[[#This Row],[Status]]="Completed",tblOnboarding[[#This Row],[Due Date]]=""),"No",IF(AND(tblOnboarding[[#This Row],[Due Date]]>=ReportDate,tblOnboarding[[#This Row],[Due Date]]<=ReportDate+DueSoonDays),"Yes","No")) -> No
A11: OB-010 | B11: WBS-1034 | C11: =IFERROR(INDEX(tblEmployees[Employee Name],MATCH(tblOnboarding[[#This Row],[Employee ID]],tblEmployees[Employee ID],0)),"ID not found") -> Karan Pawar | D11: =IFERROR(INDEX(tblEmployees[Department],MATCH(tblOnboarding[[#This Row],[Employee ID]],tblEmployees[Employee ID],0)),"") -> Sales | E11: Identity document submission | F11: HR | G11: 46275 | I11: In Progress | J11: =IF(OR(tblOnboarding[[#This Row],[Status]]="Completed",tblOnboarding[[#This Row],[Due Date]]=""),"No",IF(tblOnboarding[[#This Row],[Due Date]]<ReportDate,"Yes","No")) -> Yes | K11: =IF(tblOnboarding[[#This Row],[Overdue]]="Yes",ReportDate-tblOnboarding[[#This Row],[Due Date]],"") -> 36 | L11: =IF(OR(tblOnboarding[[#This Row],[Status]]="Completed",tblOnboarding[[#This Row],[Due Date]]=""),"No",IF(AND(tblOnboarding[[#This Row],[Due Date]]>=ReportDate,tblOnboarding[[#This Row],[Due Date]]<=ReportDate+DueSoonDays),"Yes","No")) -> No | M11: Resubmission requested - name spelling differs from offer letter
A12: OB-011 | B12: WBS-1034 | C12: =IFERROR(INDEX(tblEmployees[Employee Name],MATCH(tblOnboarding[[#This Row],[Employee ID]],tblEmployees[Employee ID],0)),"ID not found") -> Karan Pawar | D12: =IFERROR(INDEX(tblEmployees[Department],MATCH(tblOnboarding[[#This Row],[Employee ID]],tblEmployees[Employee ID],0)),"") -> Sales | E12: IT account creation | F12: IT | G12: 46274 | H12: 46279 | I12: Completed | J12: =IF(OR(tblOnboarding[[#This Row],[Status]]="Completed",tblOnboarding[[#This Row],[Due Date]]=""),"No",IF(tblOnboarding[[#This Row],[Due Date]]<ReportDate,"Yes","No")) -> No | K12: =IF(tblOnboarding[[#This Row],[Overdue]]="Yes",ReportDate-tblOnboarding[[#This Row],[Due Date]],"") | L12: =IF(OR(tblOnboarding[[#This Row],[Status]]="Completed",tblOnboarding[[#This Row],[Due Date]]=""),"No",IF(AND(tblOnboarding[[#This Row],[Due Date]]>=ReportDate,tblOnboarding[[#This Row],[Due Date]]<=ReportDate+DueSoonDays),"Yes","No")) -> No
A13: OB-012 | B13: WBS-1034 | C13: =IFERROR(INDEX(tblEmployees[Employee Name],MATCH(tblOnboarding[[#This Row],[Employee ID]],tblEmployees[Employee ID],0)),"ID not found") -> Karan Pawar | D13: =IFERROR(INDEX(tblEmployees[Department],MATCH(tblOnboarding[[#This Row],[Employee ID]],tblEmployees[Employee ID],0)),"") -> Sales | E13: Company policy acknowledgement | F13: HR | G13: 46276 | H13: 46279 | I13: Completed | J13: =IF(OR(tblOnboarding[[#This Row],[Status]]="Completed",tblOnboarding[[#This Row],[Due Date]]=""),"No",IF(tblOnboarding[[#This Row],[Due Date]]<ReportDate,"Yes","No")) -> No | K13: =IF(tblOnboarding[[#This Row],[Overdue]]="Yes",ReportDate-tblOnboarding[[#This Row],[Due Date]],"") | L13: =IF(OR(tblOnboarding[[#This Row],[Status]]="Completed",tblOnboarding[[#This Row],[Due Date]]=""),"No",IF(AND(tblOnboarding[[#This Row],[Due Date]]>=ReportDate,tblOnboarding[[#This Row],[Due Date]]<=ReportDate+DueSoonDays),"Yes","No")) -> No | M13: Delayed - employee on leave
A14: OB-013 | B14: WBS-1034 | C14: =IFERROR(INDEX(tblEmployees[Employee Name],MATCH(tblOnboarding[[#This Row],[Employee ID]],tblEmployees[Employee ID],0)),"ID not found") -> Karan Pawar | D14: =IFERROR(INDEX(tblEmployees[Department],MATCH(tblOnboarding[[#This Row],[Employee ID]],tblEmployees[Employee ID],0)),"") -> Sales | E14: HR orientation | F14: HR | G14: 46275 | H14: 46279 | I14: Completed | J14: =IF(OR(tblOnboarding[[#This Row],[Status]]="Completed",tblOnboarding[[#This Row],[Due Date]]=""),"No",IF(tblOnboarding[[#This Row],[Due Date]]<ReportDate,"Yes","No")) -> No | K14: =IF(tblOnboarding[[#This Row],[Overdue]]="Yes",ReportDate-tblOnboarding[[#This Row],[Due Date]],"") | L14: =IF(OR(tblOnboarding[[#This Row],[Status]]="Completed",tblOnboarding[[#This Row],[Due Date]]=""),"No",IF(AND(tblOnboarding[[#This Row],[Due Date]]>=ReportDate,tblOnboarding[[#This Row],[Due Date]]<=ReportDate+DueSoonDays),"Yes","No")) -> No
A15: OB-014 | B15: WBS-1034 | C15: =IFERROR(INDEX(tblEmployees[Employee Name],MATCH(tblOnboarding[[#This Row],[Employee ID]],tblEmployees[Employee ID],0)),"ID not found") -> Karan Pawar | D15: =IFERROR(INDEX(tblEmployees[Department],MATCH(tblOnboarding[[#This Row],[Employee ID]],tblEmployees[Employee ID],0)),"") -> Sales | E15: Bank details submission | F15: Payroll | G15: 46279 | H15: 46281 | I15: Completed | J15: =IF(OR(tblOnboarding[[#This Row],[Status]]="Completed",tblOnboarding[[#This Row],[Due Date]]=""),"No",IF(tblOnboarding[[#This Row],[Due Date]]<ReportDate,"Yes","No")) -> No | K15: =IF(tblOnboarding[[#This Row],[Overdue]]="Yes",ReportDate-tblOnboarding[[#This Row],[Due Date]],"") | L15: =IF(OR(tblOnboarding[[#This Row],[Status]]="Completed",tblOnboarding[[#This Row],[Due Date]]=""),"No",IF(AND(tblOnboarding[[#This Row],[Due Date]]>=ReportDate,tblOnboarding[[#This Row],[Due Date]]<=ReportDate+DueSoonDays),"Yes","No")) -> No | M15: Completed after reminder
A16: OB-015 | B16: WBS-1034 | C16: =IFERROR(INDEX(tblEmployees[Employee Name],MATCH(tblOnboarding[[#This Row],[Employee ID]],tblEmployees[Employee ID],0)),"ID not found") -> Karan Pawar | D16: =IFERROR(INDEX(tblEmployees[Department],MATCH(tblOnboarding[[#This Row],[Employee ID]],tblEmployees[Employee ID],0)),"") -> Sales | E16: Department induction | F16: Reporting Manager | G16: 46280 | H16: 46282 | I16: Completed | J16: =IF(OR(tblOnboarding[[#This Row],[Status]]="Completed",tblOnboarding[[#This Row],[Due Date]]=""),"No",IF(tblOnboarding[[#This Row],[Due Date]]<ReportDate,"Yes","No")) -> No | K16: =IF(tblOnboarding[[#This Row],[Overdue]]="Yes",ReportDate-tblOnboarding[[#This Row],[Due Date]],"") | L16: =IF(OR(tblOnboarding[[#This Row],[Status]]="Completed",tblOnboarding[[#This Row],[Due Date]]=""),"No",IF(AND(tblOnboarding[[#This Row],[Due Date]]>=ReportDate,tblOnboarding[[#This Row],[Due Date]]<=ReportDate+DueSoonDays),"Yes","No")) -> No
A17: OB-016 | B17: WBS-1034 | C17: =IFERROR(INDEX(tblEmployees[Employee Name],MATCH(tblOnboarding[[#This Row],[Employee ID]],tblEmployees[Employee ID],0)),"ID not found") -> Karan Pawar | D17: =IFERROR(INDEX(tblEmployees[Department],MATCH(tblOnboarding[[#This Row],[Employee ID]],tblEmployees[Employee ID],0)),"") -> Sales | E17: Education certificate verification | F17: HR | G17: 46287 | H17: 46290 | I17: Completed | J17: =IF(OR(tblOnboarding[[#This Row],[Status]]="Completed",tblOnboarding[[#This Row],[Due Date]]=""),"No",IF(tblOnboarding[[#This Row],[Due Date]]<ReportDate,"Yes","No")) -> No | K17: =IF(tblOnboarding[[#This Row],[Overdue]]="Yes",ReportDate-tblOnboarding[[#This Row],[Due Date]],"") | L17: =IF(OR(tblOnboarding[[#This Row],[Status]]="Completed",tblOnboarding[[#This Row],[Due Date]]=""),"No",IF(AND(tblOnboarding[[#This Row],[Due Date]]>=ReportDate,tblOnboarding[[#This Row],[Due Date]]<=ReportDate+DueSoonDays),"Yes","No")) -> No
A18: OB-017 | B18: WBS-1035 | C18: =IFERROR(INDEX(tblEmployees[Employee Name],MATCH(tblOnboarding[[#This Row],[Employee ID]],tblEmployees[Employee ID],0)),"ID not found") -> Tushar Banerjee | D18: =IFERROR(INDEX(tblEmployees[Department],MATCH(tblOnboarding[[#This Row],[Employee ID]],tblEmployees[Employee ID],0)),"") -> Operations | E18: Offer letter acknowledgement | F18: HR | G18: 46280 | H18: 46280 | I18: Completed | J18: =IF(OR(tblOnboarding[[#This Row],[Status]]="Completed",tblOnboarding[[#This Row],[Due Date]]=""),"No",IF(tblOnboarding[[#This Row],[Due Date]]<ReportDate,"Yes","No")) -> No | K18: =IF(tblOnboarding[[#This Row],[Overdue]]="Yes",ReportDate-tblOnboarding[[#This Row],[Due Date]],"") | L18: =IF(OR(tblOnboarding[[#This Row],[Status]]="Completed",tblOnboarding[[#This Row],[Due Date]]=""),"No",IF(AND(tblOnboarding[[#This Row],[Due Date]]>=ReportDate,tblOnboarding[[#This Row],[Due Date]]<=ReportDate+DueSoonDays),"Yes","No")) -> No
A19: OB-018 | B19: WBS-1035 | C19: =IFERROR(INDEX(tblEmployees[Employee Name],MATCH(tblOnboarding[[#This Row],[Employee ID]],tblEmployees[Employee ID],0)),"ID not found") -> Tushar Banerjee | D19: =IFERROR(INDEX(tblEmployees[Department],MATCH(tblOnboarding[[#This Row],[Employee ID]],tblEmployees[Employee ID],0)),"") -> Operations | E19: Identity document submission | F19: HR | G19: 46281 | H19: 46286 | I19: Completed | J19: =IF(OR(tblOnboarding[[#This Row],[Status]]="Completed",tblOnboarding[[#This Row],[Due Date]]=""),"No",IF(tblOnboarding[[#This Row],[Due Date]]<ReportDate,"Yes","No")) -> No | K19: =IF(tblOnboarding[[#This Row],[Overdue]]="Yes",ReportDate-tblOnboarding[[#This Row],[Due Date]],"") | L19: =IF(OR(tblOnboarding[[#This Row],[Status]]="Completed",tblOnboarding[[#This Row],[Due Date]]=""),"No",IF(AND(tblOnboarding[[#This Row],[Due Date]]>=ReportDate,tblOnboarding[[#This Row],[Due Date]]<=ReportDate+DueSoonDays),"Yes","No")) -> No
A20: OB-019 | B20: WBS-1035 | C20: =IFERROR(INDEX(tblEmployees[Employee Name],MATCH(tblOnboarding[[#This Row],[Employee ID]],tblEmployees[Employee ID],0)),"ID not found") -> Tushar Banerjee | D20: =IFERROR(INDEX(tblEmployees[Department],MATCH(tblOnboarding[[#This Row],[Employee ID]],tblEmployees[Employee ID],0)),"") -> Operations | E20: IT account creation | F20: IT | G20: 46280 | H20: 46286 | I20: Completed | J20: =IF(OR(tblOnboarding[[#This Row],[Status]]="Completed",tblOnboarding[[#This Row],[Due Date]]=""),"No",IF(tblOnboarding[[#This Row],[Due Date]]<ReportDate,"Yes","No")) -> No | K20: =IF(tblOnboarding[[#This Row],[Overdue]]="Yes",ReportDate-tblOnboarding[[#This Row],[Due Date]],"") | L20: =IF(OR(tblOnboarding[[#This Row],[Status]]="Completed",tblOnboarding[[#This Row],[Due Date]]=""),"No",IF(AND(tblOnboarding[[#This Row],[Due Date]]>=ReportDate,tblOnboarding[[#This Row],[Due Date]]<=ReportDate+DueSoonDays),"Yes","No")) -> No
A21: OB-020 | B21: WBS-1035 | C21: =IFERROR(INDEX(tblEmployees[Employee Name],MATCH(tblOnboarding[[#This Row],[Employee ID]],tblEmployees[Employee ID],0)),"ID not found") -> Tushar Banerjee | D21: =IFERROR(INDEX(tblEmployees[Department],MATCH(tblOnboarding[[#This Row],[Employee ID]],tblEmployees[Employee ID],0)),"") -> Operations | E21: Company policy acknowledgement | F21: HR | G21: 46282 | H21: 46283 | I21: Completed | J21: =IF(OR(tblOnboarding[[#This Row],[Status]]="Completed",tblOnboarding[[#This Row],[Due Date]]=""),"No",IF(tblOnboarding[[#This Row],[Due Date]]<ReportDate,"Yes","No")) -> No | K21: =IF(tblOnboarding[[#This Row],[Overdue]]="Yes",ReportDate-tblOnboarding[[#This Row],[Due Date]],"") | L21: =IF(OR(tblOnboarding[[#This Row],[Status]]="Completed",tblOnboarding[[#This Row],[Due Date]]=""),"No",IF(AND(tblOnboarding[[#This Row],[Due Date]]>=ReportDate,tblOnboarding[[#This Row],[Due Date]]<=ReportDate+DueSoonDays),"Yes","No")) -> No | M21: Delayed - employee on leave
A22: OB-021 | B22: WBS-1035 | C22: =IFERROR(INDEX(tblEmployees[Employee Name],MATCH(tblOnboarding[[#This Row],[Employee ID]],tblEmployees[Employee ID],0)),"ID not found") -> Tushar Banerjee | D22: =IFERROR(INDEX(tblEmployees[Department],MATCH(tblOnboarding[[#This Row],[Employee ID]],tblEmployees[Employee ID],0)),"") -> Operations | E22: HR orientation | F22: HR | G22: 46281 | H22: 46282 | I22: Completed | J22: =IF(OR(tblOnboarding[[#This Row],[Status]]="Completed",tblOnboarding[[#This Row],[Due Date]]=""),"No",IF(tblOnboarding[[#This Row],[Due Date]]<ReportDate,"Yes","No")) -> No | K22: =IF(tblOnboarding[[#This Row],[Overdue]]="Yes",ReportDate-tblOnboarding[[#This Row],[Due Date]],"") | L22: =IF(OR(tblOnboarding[[#This Row],[Status]]="Completed",tblOnboarding[[#This Row],[Due Date]]=""),"No",IF(AND(tblOnboarding[[#This Row],[Due Date]]>=ReportDate,tblOnboarding[[#This Row],[Due Date]]<=ReportDate+DueSoonDays),"Yes","No")) -> No
A23: OB-022 | B23: WBS-1035 | C23: =IFERROR(INDEX(tblEmployees[Employee Name],MATCH(tblOnboarding[[#This Row],[Employee ID]],tblEmployees[Employee ID],0)),"ID not found") -> Tushar Banerjee | D23: =IFERROR(INDEX(tblEmployees[Department],MATCH(tblOnboarding[[#This Row],[Employee ID]],tblEmployees[Employee ID],0)),"") -> Operations | E23: Bank details submission | F23: Payroll | G23: 46286 | I23: Pending | J23: =IF(OR(tblOnboarding[[#This Row],[Status]]="Completed",tblOnboarding[[#This Row],[Due Date]]=""),"No",IF(tblOnboarding[[#This Row],[Due Date]]<ReportDate,"Yes","No")) -> Yes | K23: =IF(tblOnboarding[[#This Row],[Overdue]]="Yes",ReportDate-tblOnboarding[[#This Row],[Due Date]],"") -> 25 | L23: =IF(OR(tblOnboarding[[#This Row],[Status]]="Completed",tblOnboarding[[#This Row],[Due Date]]=""),"No",IF(AND(tblOnboarding[[#This Row],[Due Date]]>=ReportDate,tblOnboarding[[#This Row],[Due Date]]<=ReportDate+DueSoonDays),"Yes","No")) -> No | M23: Cancelled cheque not yet received - reminder sent 13-Oct
A24: OB-023 | B24: WBS-1035 | C24: =IFERROR(INDEX(tblEmployees[Employee Name],MATCH(tblOnboarding[[#This Row],[Employee ID]],tblEmployees[Employee ID],0)),"ID not found") -> Tushar Banerjee | D24: =IFERROR(INDEX(tblEmployees[Department],MATCH(tblOnboarding[[#This Row],[Employee ID]],tblEmployees[Employee ID],0)),"") -> Operations | E24: Department induction | F24: Reporting Manager | G24: 46286 | H24: 46287 | I24: Completed | J24: =IF(OR(tblOnboarding[[#This Row],[Status]]="Completed",tblOnboarding[[#This Row],[Due Date]]=""),"No",IF(tblOnboarding[[#This Row],[Due Date]]<ReportDate,"Yes","No")) -> No | K24: =IF(tblOnboarding[[#This Row],[Overdue]]="Yes",ReportDate-tblOnboarding[[#This Row],[Due Date]],"") | L24: =IF(OR(tblOnboarding[[#This Row],[Status]]="Completed",tblOnboarding[[#This Row],[Due Date]]=""),"No",IF(AND(tblOnboarding[[#This Row],[Due Date]]>=ReportDate,tblOnboarding[[#This Row],[Due Date]]<=ReportDate+DueSoonDays),"Yes","No")) -> No
A25: OB-024 | B25: WBS-1035 | C25: =IFERROR(INDEX(tblEmployees[Employee Name],MATCH(tblOnboarding[[#This Row],[Employee ID]],tblEmployees[Employee ID],0)),"ID not found") -> Tushar Banerjee | D25: =IFERROR(INDEX(tblEmployees[Department],MATCH(tblOnboarding[[#This Row],[Employee ID]],tblEmployees[Employee ID],0)),"") -> Operations | E25: Education certificate verification | F25: HR | G25: 46293 | H25: 46294 | I25: Completed | J25: =IF(OR(tblOnboarding[[#This Row],[Status]]="Completed",tblOnboarding[[#This Row],[Due Date]]=""),"No",IF(tblOnboarding[[#This Row],[Due Date]]<ReportDate,"Yes","No")) -> No | K25: =IF(tblOnboarding[[#This Row],[Overdue]]="Yes",ReportDate-tblOnboarding[[#This Row],[Due Date]],"") | L25: =IF(OR(tblOnboarding[[#This Row],[Status]]="Completed",tblOnboarding[[#This Row],[Due Date]]=""),"No",IF(AND(tblOnboarding[[#This Row],[Due Date]]>=ReportDate,tblOnboarding[[#This Row],[Due Date]]<=ReportDate+DueSoonDays),"Yes","No")) -> No
A26: OB-025 | B26: WBS-1036 | C26: =IFERROR(INDEX(tblEmployees[Employee Name],MATCH(tblOnboarding[[#This Row],[Employee ID]],tblEmployees[Employee ID],0)),"ID not found") -> Priya Kadam | D26: =IFERROR(INDEX(tblEmployees[Department],MATCH(tblOnboarding[[#This Row],[Employee ID]],tblEmployees[Employee ID],0)),"") -> Customer Support | E26: Offer letter acknowledgement | F26: HR | G26: 46280 | H26: 46279 | I26: Completed | J26: =IF(OR(tblOnboarding[[#This Row],[Status]]="Completed",tblOnboarding[[#This Row],[Due Date]]=""),"No",IF(tblOnboarding[[#This Row],[Due Date]]<ReportDate,"Yes","No")) -> No | K26: =IF(tblOnboarding[[#This Row],[Overdue]]="Yes",ReportDate-tblOnboarding[[#This Row],[Due Date]],"") | L26: =IF(OR(tblOnboarding[[#This Row],[Status]]="Completed",tblOnboarding[[#This Row],[Due Date]]=""),"No",IF(AND(tblOnboarding[[#This Row],[Due Date]]>=ReportDate,tblOnboarding[[#This Row],[Due Date]]<=ReportDate+DueSoonDays),"Yes","No")) -> No
A27: OB-026 | B27: WBS-1036 | C27: =IFERROR(INDEX(tblEmployees[Employee Name],MATCH(tblOnboarding[[#This Row],[Employee ID]],tblEmployees[Employee ID],0)),"ID not found") -> Priya Kadam | D27: =IFERROR(INDEX(tblEmployees[Department],MATCH(tblOnboarding[[#This Row],[Employee ID]],tblEmployees[Employee ID],0)),"") -> Customer Support | E27: Identity document submission | F27: HR | G27: 46281 | I27: Pending | J27: =IF(OR(tblOnboarding[[#This Row],[Status]]="Completed",tblOnboarding[[#This Row],[Due Date]]=""),"No",IF(tblOnboarding[[#This Row],[Due Date]]<ReportDate,"Yes","No")) -> Yes | K27: =IF(tblOnboarding[[#This Row],[Overdue]]="Yes",ReportDate-tblOnboarding[[#This Row],[Due Date]],"") -> 30 | L27: =IF(OR(tblOnboarding[[#This Row],[Status]]="Completed",tblOnboarding[[#This Row],[Due Date]]=""),"No",IF(AND(tblOnboarding[[#This Row],[Due Date]]>=ReportDate,tblOnboarding[[#This Row],[Due Date]]<=ReportDate+DueSoonDays),"Yes","No")) -> No
A28: OB-027 | B28: WBS-1036 | C28: =IFERROR(INDEX(tblEmployees[Employee Name],MATCH(tblOnboarding[[#This Row],[Employee ID]],tblEmployees[Employee ID],0)),"ID not found") -> Priya Kadam | D28: =IFERROR(INDEX(tblEmployees[Department],MATCH(tblOnboarding[[#This Row],[Employee ID]],tblEmployees[Employee ID],0)),"") -> Customer Support | E28: IT account creation | F28: IT | G28: 46280 | H28: 46280 | I28: Completed | J28: =IF(OR(tblOnboarding[[#This Row],[Status]]="Completed",tblOnboarding[[#This Row],[Due Date]]=""),"No",IF(tblOnboarding[[#This Row],[Due Date]]<ReportDate,"Yes","No")) -> No | K28: =IF(tblOnboarding[[#This Row],[Overdue]]="Yes",ReportDate-tblOnboarding[[#This Row],[Due Date]],"") | L28: =IF(OR(tblOnboarding[[#This Row],[Status]]="Completed",tblOnboarding[[#This Row],[Due Date]]=""),"No",IF(AND(tblOnboarding[[#This Row],[Due Date]]>=ReportDate,tblOnboarding[[#This Row],[Due Date]]<=ReportDate+DueSoonDays),"Yes","No")) -> No
A29: OB-028 | B29: WBS-1036 | C29: =IFERROR(INDEX(tblEmployees[Employee Name],MATCH(tblOnboarding[[#This Row],[Employee ID]],tblEmployees[Employee ID],0)),"ID not found") -> Priya Kadam | D29: =IFERROR(INDEX(tblEmployees[Department],MATCH(tblOnboarding[[#This Row],[Employee ID]],tblEmployees[Employee ID],0)),"") -> Customer Support | E29: Company policy acknowledgement | F29: HR | G29: 46282 | H29: 46281 | I29: Completed | J29: =IF(OR(tblOnboarding[[#This Row],[Status]]="Completed",tblOnboarding[[#This Row],[Due Date]]=""),"No",IF(tblOnboarding[[#This Row],[Due Date]]<ReportDate,"Yes","No")) -> No | K29: =IF(tblOnboarding[[#This Row],[Overdue]]="Yes",ReportDate-tblOnboarding[[#This Row],[Due Date]],"") | L29: =IF(OR(tblOnboarding[[#This Row],[Status]]="Completed",tblOnboarding[[#This Row],[Due Date]]=""),"No",IF(AND(tblOnboarding[[#This Row],[Due Date]]>=ReportDate,tblOnboarding[[#This Row],[Due Date]]<=ReportDate+DueSoonDays),"Yes","No")) -> No
A30: OB-029 | B30: WBS-1036 | C30: =IFERROR(INDEX(tblEmployees[Employee Name],MATCH(tblOnboarding[[#This Row],[Employee ID]],tblEmployees[Employee ID],0)),"ID not found") -> Priya Kadam | D30: =IFERROR(INDEX(tblEmployees[Department],MATCH(tblOnboarding[[#This Row],[Employee ID]],tblEmployees[Employee ID],0)),"") -> Customer Support | E30: HR orientation | F30: HR | G30: 46281 | H30: 46283 | I30: Completed | J30: =IF(OR(tblOnboarding[[#This Row],[Status]]="Completed",tblOnboarding[[#This Row],[Due Date]]=""),"No",IF(tblOnboarding[[#This Row],[Due Date]]<ReportDate,"Yes","No")) -> No | K30: =IF(tblOnboarding[[#This Row],[Overdue]]="Yes",ReportDate-tblOnboarding[[#This Row],[Due Date]],"") | L30: =IF(OR(tblOnboarding[[#This Row],[Status]]="Completed",tblOnboarding[[#This Row],[Due Date]]=""),"No",IF(AND(tblOnboarding[[#This Row],[Due Date]]>=ReportDate,tblOnboarding[[#This Row],[Due Date]]<=ReportDate+DueSoonDays),"Yes","No")) -> No | M30: Completed after reminder
A31: OB-030 | B31: WBS-1036 | C31: =IFERROR(INDEX(tblEmployees[Employee Name],MATCH(tblOnboarding[[#This Row],[Employee ID]],tblEmployees[Employee ID],0)),"ID not found") -> Priya Kadam | D31: =IFERROR(INDEX(tblEmployees[Department],MATCH(tblOnboarding[[#This Row],[Employee ID]],tblEmployees[Employee ID],0)),"") -> Customer Support | E31: Bank details submission | F31: Payroll | G31: 46286 | I31: Pending | J31: =IF(OR(tblOnboarding[[#This Row],[Status]]="Completed",tblOnboarding[[#This Row],[Due Date]]=""),"No",IF(tblOnboarding[[#This Row],[Due Date]]<ReportDate,"Yes","No")) -> Yes | K31: =IF(tblOnboarding[[#This Row],[Overdue]]="Yes",ReportDate-tblOnboarding[[#This Row],[Due Date]],"") -> 25 | L31: =IF(OR(tblOnboarding[[#This Row],[Status]]="Completed",tblOnboarding[[#This Row],[Due Date]]=""),"No",IF(AND(tblOnboarding[[#This Row],[Due Date]]>=ReportDate,tblOnboarding[[#This Row],[Due Date]]<=ReportDate+DueSoonDays),"Yes","No")) -> No | M31: Cancelled cheque not yet received - reminder sent 15-Oct
A32: OB-031 | B32: WBS-1036 | C32: =IFERROR(INDEX(tblEmployees[Employee Name],MATCH(tblOnboarding[[#This Row],[Employee ID]],tblEmployees[Employee ID],0)),"ID not found") -> Priya Kadam | D32: =IFERROR(INDEX(tblEmployees[Department],MATCH(tblOnboarding[[#This Row],[Employee ID]],tblEmployees[Employee ID],0)),"") -> Customer Support | E32: Department induction | F32: Reporting Manager | G32: 46286 | H32: 46286 | I32: Completed | J32: =IF(OR(tblOnboarding[[#This Row],[Status]]="Completed",tblOnboarding[[#This Row],[Due Date]]=""),"No",IF(tblOnboarding[[#This Row],[Due Date]]<ReportDate,"Yes","No")) -> No | K32: =IF(tblOnboarding[[#This Row],[Overdue]]="Yes",ReportDate-tblOnboarding[[#This Row],[Due Date]],"") | L32: =IF(OR(tblOnboarding[[#This Row],[Status]]="Completed",tblOnboarding[[#This Row],[Due Date]]=""),"No",IF(AND(tblOnboarding[[#This Row],[Due Date]]>=ReportDate,tblOnboarding[[#This Row],[Due Date]]<=ReportDate+DueSoonDays),"Yes","No")) -> No
A33: OB-032 | B33: WBS-1036 | C33: =IFERROR(INDEX(tblEmployees[Employee Name],MATCH(tblOnboarding[[#This Row],[Employee ID]],tblEmployees[Employee ID],0)),"ID not found") -> Priya Kadam | D33: =IFERROR(INDEX(tblEmployees[Department],MATCH(tblOnboarding[[#This Row],[Employee ID]],tblEmployees[Employee ID],0)),"") -> Customer Support | E33: Education certificate verification | F33: HR | G33: 46293 | I33: Pending | J33: =IF(OR(tblOnboarding[[#This Row],[Status]]="Completed",tblOnboarding[[#This Row],[Due Date]]=""),"No",IF(tblOnboarding[[#This Row],[Due Date]]<ReportDate,"Yes","No")) -> Yes | K33: =IF(tblOnboarding[[#This Row],[Overdue]]="Yes",ReportDate-tblOnboarding[[#This Row],[Due Date]],"") -> 18 | L33: =IF(OR(tblOnboarding[[#This Row],[Status]]="Completed",tblOnboarding[[#This Row],[Due Date]]=""),"No",IF(AND(tblOnboarding[[#This Row],[Due Date]]>=ReportDate,tblOnboarding[[#This Row],[Due Date]]<=ReportDate+DueSoonDays),"Yes","No")) -> No | M33: Degree certificate copy awaited from employee
A34: OB-033 | B34: WBS-1037 | C34: =IFERROR(INDEX(tblEmployees[Employee Name],MATCH(tblOnboarding[[#This Row],[Employee ID]],tblEmployees[Employee ID],0)),"ID not found") -> Pooja Thakur | D34: =IFERROR(INDEX(tblEmployees[Department],MATCH(tblOnboarding[[#This Row],[Employee ID]],tblEmployees[Employee ID],0)),"") -> Operations | E34: Offer letter acknowledgement | F34: HR | G34: 46282 | H34: 46286 | I34: Completed | J34: =IF(OR(tblOnboarding[[#This Row],[Status]]="Completed",tblOnboarding[[#This Row],[Due Date]]=""),"No",IF(tblOnboarding[[#This Row],[Due Date]]<ReportDate,"Yes","No")) -> No | K34: =IF(tblOnboarding[[#This Row],[Overdue]]="Yes",ReportDate-tblOnboarding[[#This Row],[Due Date]],"") | L34: =IF(OR(tblOnboarding[[#This Row],[Status]]="Completed",tblOnboarding[[#This Row],[Due Date]]=""),"No",IF(AND(tblOnboarding[[#This Row],[Due Date]]>=ReportDate,tblOnboarding[[#This Row],[Due Date]]<=ReportDate+DueSoonDays),"Yes","No")) -> No
A35: OB-034 | B35: WBS-1037 | C35: =IFERROR(INDEX(tblEmployees[Employee Name],MATCH(tblOnboarding[[#This Row],[Employee ID]],tblEmployees[Employee ID],0)),"ID not found") -> Pooja Thakur | D35: =IFERROR(INDEX(tblEmployees[Department],MATCH(tblOnboarding[[#This Row],[Employee ID]],tblEmployees[Employee ID],0)),"") -> Operations | E35: Identity document submission | F35: HR | G35: 46283 | H35: 46283 | I35: Completed | J35: =IF(OR(tblOnboarding[[#This Row],[Status]]="Completed",tblOnboarding[[#This Row],[Due Date]]=""),"No",IF(tblOnboarding[[#This Row],[Due Date]]<ReportDate,"Yes","No")) -> No | K35: =IF(tblOnboarding[[#This Row],[Overdue]]="Yes",ReportDate-tblOnboarding[[#This Row],[Due Date]],"") | L35: =IF(OR(tblOnboarding[[#This Row],[Status]]="Completed",tblOnboarding[[#This Row],[Due Date]]=""),"No",IF(AND(tblOnboarding[[#This Row],[Due Date]]>=ReportDate,tblOnboarding[[#This Row],[Due Date]]<=ReportDate+DueSoonDays),"Yes","No")) -> No
A36: OB-035 | B36: WBS-1037 | C36: =IFERROR(INDEX(tblEmployees[Employee Name],MATCH(tblOnboarding[[#This Row],[Employee ID]],tblEmployees[Employee ID],0)),"ID not found") -> Pooja Thakur | D36: =IFERROR(INDEX(tblEmployees[Department],MATCH(tblOnboarding[[#This Row],[Employee ID]],tblEmployees[Employee ID],0)),"") -> Operations | E36: IT account creation | F36: IT | G36: 46282 | H36: 46282 | I36: Completed | J36: =IF(OR(tblOnboarding[[#This Row],[Status]]="Completed",tblOnboarding[[#This Row],[Due Date]]=""),"No",IF(tblOnboarding[[#This Row],[Due Date]]<ReportDate,"Yes","No")) -> No | K36: =IF(tblOnboarding[[#This Row],[Overdue]]="Yes",ReportDate-tblOnboarding[[#This Row],[Due Date]],"") | L36: =IF(OR(tblOnboarding[[#This Row],[Status]]="Completed",tblOnboarding[[#This Row],[Due Date]]=""),"No",IF(AND(tblOnboarding[[#This Row],[Due Date]]>=ReportDate,tblOnboarding[[#This Row],[Due Date]]<=ReportDate+DueSoonDays),"Yes","No")) -> No
A37: OB-036 | B37: WBS-1037 | C37: =IFERROR(INDEX(tblEmployees[Employee Name],MATCH(tblOnboarding[[#This Row],[Employee ID]],tblEmployees[Employee ID],0)),"ID not found") -> Pooja Thakur | D37: =IFERROR(INDEX(tblEmployees[Department],MATCH(tblOnboarding[[#This Row],[Employee ID]],tblEmployees[Employee ID],0)),"") -> Operations | E37: Company policy acknowledgement | F37: HR | G37: 46286 | H37: 46287 | I37: Completed | J37: =IF(OR(tblOnboarding[[#This Row],[Status]]="Completed",tblOnboarding[[#This Row],[Due Date]]=""),"No",IF(tblOnboarding[[#This Row],[Due Date]]<ReportDate,"Yes","No")) -> No | K37: =IF(tblOnboarding[[#This Row],[Overdue]]="Yes",ReportDate-tblOnboarding[[#This Row],[Due Date]],"") | L37: =IF(OR(tblOnboarding[[#This Row],[Status]]="Completed",tblOnboarding[[#This Row],[Due Date]]=""),"No",IF(AND(tblOnboarding[[#This Row],[Due Date]]>=ReportDate,tblOnboarding[[#This Row],[Due Date]]<=ReportDate+DueSoonDays),"Yes","No")) -> No
A38: OB-037 | B38: WBS-1037 | C38: =IFERROR(INDEX(tblEmployees[Employee Name],MATCH(tblOnboarding[[#This Row],[Employee ID]],tblEmployees[Employee ID],0)),"ID not found") -> Pooja Thakur | D38: =IFERROR(INDEX(tblEmployees[Department],MATCH(tblOnboarding[[#This Row],[Employee ID]],tblEmployees[Employee ID],0)),"") -> Operations | E38: HR orientation | F38: HR | G38: 46283 | H38: 46283 | I38: Completed | J38: =IF(OR(tblOnboarding[[#This Row],[Status]]="Completed",tblOnboarding[[#This Row],[Due Date]]=""),"No",IF(tblOnboarding[[#This Row],[Due Date]]<ReportDate,"Yes","No")) -> No | K38: =IF(tblOnboarding[[#This Row],[Overdue]]="Yes",ReportDate-tblOnboarding[[#This Row],[Due Date]],"") | L38: =IF(OR(tblOnboarding[[#This Row],[Status]]="Completed",tblOnboarding[[#This Row],[Due Date]]=""),"No",IF(AND(tblOnboarding[[#This Row],[Due Date]]>=ReportDate,tblOnboarding[[#This Row],[Due Date]]<=ReportDate+DueSoonDays),"Yes","No")) -> No
A39: OB-038 | B39: WBS-1037 | C39: =IFERROR(INDEX(tblEmployees[Employee Name],MATCH(tblOnboarding[[#This Row],[Employee ID]],tblEmployees[Employee ID],0)),"ID not found") -> Pooja Thakur | D39: =IFERROR(INDEX(tblEmployees[Department],MATCH(tblOnboarding[[#This Row],[Employee ID]],tblEmployees[Employee ID],0)),"") -> Operations | E39: Bank details submission | F39: Payroll | G39: 46286 | H39: 46287 | I39: Completed | J39: =IF(OR(tblOnboarding[[#This Row],[Status]]="Completed",tblOnboarding[[#This Row],[Due Date]]=""),"No",IF(tblOnboarding[[#This Row],[Due Date]]<ReportDate,"Yes","No")) -> No | K39: =IF(tblOnboarding[[#This Row],[Overdue]]="Yes",ReportDate-tblOnboarding[[#This Row],[Due Date]],"") | L39: =IF(OR(tblOnboarding[[#This Row],[Status]]="Completed",tblOnboarding[[#This Row],[Due Date]]=""),"No",IF(AND(tblOnboarding[[#This Row],[Due Date]]>=ReportDate,tblOnboarding[[#This Row],[Due Date]]<=ReportDate+DueSoonDays),"Yes","No")) -> No
A40: OB-039 | B40: WBS-1037 | C40: =IFERROR(INDEX(tblEmployees[Employee Name],MATCH(tblOnboarding[[#This Row],[Employee ID]],tblEmployees[Employee ID],0)),"ID not found") -> Pooja Thakur | D40: =IFERROR(INDEX(tblEmployees[Department],MATCH(tblOnboarding[[#This Row],[Employee ID]],tblEmployees[Employee ID],0)),"") -> Operations | E40: Department induction | F40: Reporting Manager | G40: 46288 | H40: 46293 | I40: Completed | J40: =IF(OR(tblOnboarding[[#This Row],[Status]]="Completed",tblOnboarding[[#This Row],[Due Date]]=""),"No",IF(tblOnboarding[[#This Row],[Due Date]]<ReportDate,"Yes","No")) -> No | K40: =IF(tblOnboarding[[#This Row],[Overdue]]="Yes",ReportDate-tblOnboarding[[#This Row],[Due Date]],"") | L40: =IF(OR(tblOnboarding[[#This Row],[Status]]="Completed",tblOnboarding[[#This Row],[Due Date]]=""),"No",IF(AND(tblOnboarding[[#This Row],[Due Date]]>=ReportDate,tblOnboarding[[#This Row],[Due Date]]<=ReportDate+DueSoonDays),"Yes","No")) -> No
...

Sheet Document Checklist
A1: Employee ID | B1: Employee Name | C1: Document Type | D1: Submission Status | E1: Verification Status | F1: Document Status | G1: Remarks
A2: WBS-1033 | B2: =IFERROR(INDEX(tblEmployees[Employee Name],MATCH(tblDocuments[[#This Row],[Employee ID]],tblEmployees[Employee ID],0)),"ID not found") -> Siddharth Agarwal | C2: Identity Proof | D2: Submitted | E2: Verified | F2: =IF(tblDocuments[[#This Row],[Submission Status]]<>"Submitted","Not Submitted",IF(tblDocuments[[#This Row],[Verification Status]]="Verified","Verified",IF(tblDocuments[[#This Row],[Verification Status]]="Needs Resubmission","Needs Resubmission","Awaiting Verification"))) -> Verified
A3: WBS-1033 | B3: =IFERROR(INDEX(tblEmployees[Employee Name],MATCH(tblDocuments[[#This Row],[Employee ID]],tblEmployees[Employee ID],0)),"ID not found") -> Siddharth Agarwal | C3: Address Proof | D3: Submitted | E3: Verified | F3: =IF(tblDocuments[[#This Row],[Submission Status]]<>"Submitted","Not Submitted",IF(tblDocuments[[#This Row],[Verification Status]]="Verified","Verified",IF(tblDocuments[[#This Row],[Verification Status]]="Needs Resubmission","Needs Resubmission","Awaiting Verification"))) -> Verified
A4: WBS-1033 | B4: =IFERROR(INDEX(tblEmployees[Employee Name],MATCH(tblDocuments[[#This Row],[Employee ID]],tblEmployees[Employee ID],0)),"ID not found") -> Siddharth Agarwal | C4: Education Certificates | D4: Submitted | E4: Not Verified | F4: =IF(tblDocuments[[#This Row],[Submission Status]]<>"Submitted","Not Submitted",IF(tblDocuments[[#This Row],[Verification Status]]="Verified","Verified",IF(tblDocuments[[#This Row],[Verification Status]]="Needs Resubmission","Needs Resubmission","Awaiting Verification"))) -> Awaiting Verification | G4: Sent to verification agency
A5: WBS-1033 | B5: =IFERROR(INDEX(tblEmployees[Employee Name],MATCH(tblDocuments[[#This Row],[Employee ID]],tblEmployees[Employee ID],0)),"ID not found") -> Siddharth Agarwal | C5: Bank Account Proof | D5: Submitted | E5: Not Verified | F5: =IF(tblDocuments[[#This Row],[Submission Status]]<>"Submitted","Not Submitted",IF(tblDocuments[[#This Row],[Verification Status]]="Verified","Verified",IF(tblDocuments[[#This Row],[Verification Status]]="Needs Resubmission","Needs Resubmission","Awaiting Verification"))) -> Awaiting Verification
A6: WBS-1034 | B6: =IFERROR(INDEX(tblEmployees[Employee Name],MATCH(tblDocuments[[#This Row],[Employee ID]],tblEmployees[Employee ID],0)),"ID not found") -> Karan Pawar | C6: Identity Proof | D6: Submitted | E6: Needs Resubmission | F6: =IF(tblDocuments[[#This Row],[Submission Status]]<>"Submitted","Not Submitted",IF(tblDocuments[[#This Row],[Verification Status]]="Verified","Verified",IF(tblDocuments[[#This Row],[Verification Status]]="Needs Resubmission","Needs Resubmission","Awaiting Verification"))) -> Needs Resubmission | G6: Name spelling differs from offer letter - resubmission requested
A7: WBS-1034 | B7: =IFERROR(INDEX(tblEmployees[Employee Name],MATCH(tblDocuments[[#This Row],[Employee ID]],tblEmployees[Employee ID],0)),"ID not found") -> Karan Pawar | C7: Address Proof | D7: Submitted | E7: Verified | F7: =IF(tblDocuments[[#This Row],[Submission Status]]<>"Submitted","Not Submitted",IF(tblDocuments[[#This Row],[Verification Status]]="Verified","Verified",IF(tblDocuments[[#This Row],[Verification Status]]="Needs Resubmission","Needs Resubmission","Awaiting Verification"))) -> Verified
A8: WBS-1034 | B8: =IFERROR(INDEX(tblEmployees[Employee Name],MATCH(tblDocuments[[#This Row],[Employee ID]],tblEmployees[Employee ID],0)),"ID not found") -> Karan Pawar | C8: Education Certificates | D8: Submitted | E8: Verified | F8: =IF(tblDocuments[[#This Row],[Submission Status]]<>"Submitted","Not Submitted",IF(tblDocuments[[#This Row],[Verification Status]]="Verified","Verified",IF(tblDocuments[[#This Row],[Verification Status]]="Needs Resubmission","Needs Resubmission","Awaiting Verification"))) -> Verified
A9: WBS-1034 | B9: =IFERROR(INDEX(tblEmployees[Employee Name],MATCH(tblDocuments[[#This Row],[Employee ID]],tblEmployees[Employee ID],0)),"ID not found") -> Karan Pawar | C9: Bank Account Proof | D9: Submitted | E9: Verified | F9: =IF(tblDocuments[[#This Row],[Submission Status]]<>"Submitted","Not Submitted",IF(tblDocuments[[#This Row],[Verification Status]]="Verified","Verified",IF(tblDocuments[[#This Row],[Verification Status]]="Needs Resubmission","Needs Resubmission","Awaiting Verification"))) -> Verified
A10: WBS-1035 | B10: =IFERROR(INDEX(tblEmployees[Employee Name],MATCH(tblDocuments[[#This Row],[Employee ID]],tblEmployees[Employee ID],0)),"ID not found") -> Tushar Banerjee | C10: Identity Proof | D10: Submitted | E10: Verified | F10: =IF(tblDocuments[[#This Row],[Submission Status]]<>"Submitted","Not Submitted",IF(tblDocuments[[#This Row],[Verification Status]]="Verified","Verified",IF(tblDocuments[[#This Row],[Verification Status]]="Needs Resubmission","Needs Resubmission","Awaiting Verification"))) -> Verified
A11: WBS-1035 | B11: =IFERROR(INDEX(tblEmployees[Employee Name],MATCH(tblDocuments[[#This Row],[Employee ID]],tblEmployees[Employee ID],0)),"ID not found") -> Tushar Banerjee | C11: Address Proof | D11: Submitted | E11: Verified | F11: =IF(tblDocuments[[#This Row],[Submission Status]]<>"Submitted","Not Submitted",IF(tblDocuments[[#This Row],[Verification Status]]="Verified","Verified",IF(tblDocuments[[#This Row],[Verification Status]]="Needs Resubmission","Needs Resubmission","Awaiting Verification"))) -> Verified
A12: WBS-1035 | B12: =IFERROR(INDEX(tblEmployees[Employee Name],MATCH(tblDocuments[[#This Row],[Employee ID]],tblEmployees[Employee ID],0)),"ID not found") -> Tushar Banerjee | C12: Education Certificates | D12: Submitted | E12: Verified | F12: =IF(tblDocuments[[#This Row],[Submission Status]]<>"Submitted","Not Submitted",IF(tblDocuments[[#This Row],[Verification Status]]="Verified","Verified",IF(tblDocuments[[#This Row],[Verification Status]]="Needs Resubmission","Needs Resubmission","Awaiting Verification"))) -> Verified
A13: WBS-1035 | B13: =IFERROR(INDEX(tblEmployees[Employee Name],MATCH(tblDocuments[[#This Row],[Employee ID]],tblEmployees[Employee ID],0)),"ID not found") -> Tushar Banerjee | C13: Bank Account Proof | D13: Not Submitted | E13: Not Verified | F13: =IF(tblDocuments[[#This Row],[Submission Status]]<>"Submitted","Not Submitted",IF(tblDocuments[[#This Row],[Verification Status]]="Verified","Verified",IF(tblDocuments[[#This Row],[Verification Status]]="Needs Resubmission","Needs Resubmission","Awaiting Verification"))) -> Not Submitted | G13: Cheque / passbook copy awaited
A14: WBS-1036 | B14: =IFERROR(INDEX(tblEmployees[Employee Name],MATCH(tblDocuments[[#This Row],[Employee ID]],tblEmployees[Employee ID],0)),"ID not found") -> Priya Kadam | C14: Identity Proof | D14: Not Submitted | E14: Not Verified | F14: =IF(tblDocuments[[#This Row],[Submission Status]]<>"Submitted","Not Submitted",IF(tblDocuments[[#This Row],[Verification Status]]="Verified","Verified",IF(tblDocuments[[#This Row],[Verification Status]]="Needs Resubmission","Needs Resubmission","Awaiting Verification"))) -> Not Submitted | G14: Reminder sent 14-Oct
A15: WBS-1036 | B15: =IFERROR(INDEX(tblEmployees[Employee Name],MATCH(tblDocuments[[#This Row],[Employee ID]],tblEmployees[Employee ID],0)),"ID not found") -> Priya Kadam | C15: Address Proof | D15: Submitted | E15: Verified | F15: =IF(tblDocuments[[#This Row],[Submission Status]]<>"Submitted","Not Submitted",IF(tblDocuments[[#This Row],[Verification Status]]="Verified","Verified",IF(tblDocuments[[#This Row],[Verification Status]]="Needs Resubmission","Needs Resubmission","Awaiting Verification"))) -> Verified
A16: WBS-1036 | B16: =IFERROR(INDEX(tblEmployees[Employee Name],MATCH(tblDocuments[[#This Row],[Employee ID]],tblEmployees[Employee ID],0)),"ID not found") -> Priya Kadam | C16: Education Certificates | D16: Not Submitted | E16: Not Verified | F16: =IF(tblDocuments[[#This Row],[Submission Status]]<>"Submitted","Not Submitted",IF(tblDocuments[[#This Row],[Verification Status]]="Verified","Verified",IF(tblDocuments[[#This Row],[Verification Status]]="Needs Resubmission","Needs Resubmission","Awaiting Verification"))) -> Not Submitted | G16: Certificate copy awaited
A17: WBS-1036 | B17: =IFERROR(INDEX(tblEmployees[Employee Name],MATCH(tblDocuments[[#This Row],[Employee ID]],tblEmployees[Employee ID],0)),"ID not found") -> Priya Kadam | C17: Bank Account Proof | D17: Not Submitted | E17: Not Verified | F17: =IF(tblDocuments[[#This Row],[Submission Status]]<>"Submitted","Not Submitted",IF(tblDocuments[[#This Row],[Verification Status]]="Verified","Verified",IF(tblDocuments[[#This Row],[Verification Status]]="Needs Resubmission","Needs Resubmission","Awaiting Verification"))) -> Not Submitted | G17: Cheque / passbook copy awaited
A18: WBS-1037 | B18: =IFERROR(INDEX(tblEmployees[Employee Name],MATCH(tblDocuments[[#This Row],[Employee ID]],tblEmployees[Employee ID],0)),"ID not found") -> Pooja Thakur | C18: Identity Proof | D18: Submitted | E18: Verified | F18: =IF(tblDocuments[[#This Row],[Submission Status]]<>"Submitted","Not Submitted",IF(tblDocuments[[#This Row],[Verification Status]]="Verified","Verified",IF(tblDocuments[[#This Row],[Verification Status]]="Needs Resubmission","Needs Resubmission","Awaiting Verification"))) -> Verified
A19: WBS-1037 | B19: =IFERROR(INDEX(tblEmployees[Employee Name],MATCH(tblDocuments[[#This Row],[Employee ID]],tblEmployees[Employee ID],0)),"ID not found") -> Pooja Thakur | C19: Address Proof | D19: Submitted | E19: Verified | F19: =IF(tblDocuments[[#This Row],[Submission Status]]<>"Submitted","Not Submitted",IF(tblDocuments[[#This Row],[Verification Status]]="Verified","Verified",IF(tblDocuments[[#This Row],[Verification Status]]="Needs Resubmission","Needs Resubmission","Awaiting Verification"))) -> Verified
A20: WBS-1037 | B20: =IFERROR(INDEX(tblEmployees[Employee Name],MATCH(tblDocuments[[#This Row],[Employee ID]],tblEmployees[Employee ID],0)),"ID not found") -> Pooja Thakur | C20: Education Certificates | D20: Submitted | E20: Not Verified | F20: =IF(tblDocuments[[#This Row],[Submission Status]]<>"Submitted","Not Submitted",IF(tblDocuments[[#This Row],[Verification Status]]="Verified","Verified",IF(tblDocuments[[#This Row],[Verification Status]]="Needs Resubmission","Needs Resubmission","Awaiting Verification"))) -> Awaiting Verification | G20: Sent to verification agency
A21: WBS-1037 | B21: =IFERROR(INDEX(tblEmployees[Employee Name],MATCH(tblDocuments[[#This Row],[Employee ID]],tblEmployees[Employee ID],0)),"ID not found") -> Pooja Thakur | C21: Bank Account Proof | D21: Submitted | E21: Verified | F21: =IF(tblDocuments[[#This Row],[Submission Status]]<>"Submitted","Not Submitted",IF(tblDocuments[[#This Row],[Verification Status]]="Verified","Verified",IF(tblDocuments[[#This Row],[Verification Status]]="Needs Resubmission","Needs Resubmission","Awaiting Verification"))) -> Verified
A22: WBS-1038 | B22: =IFERROR(INDEX(tblEmployees[Employee Name],MATCH(tblDocuments[[#This Row],[Employee ID]],tblEmployees[Employee ID],0)),"ID not found") -> Vaishnavi Pillai | C22: Identity Proof | D22: Submitted | E22: Verified | F22: =IF(tblDocuments[[#This Row],[Submission Status]]<>"Submitted","Not Submitted",IF(tblDocuments[[#This Row],[Verification Status]]="Verified","Verified",IF(tblDocuments[[#This Row],[Verification Status]]="Needs Resubmission","Needs Resubmission","Awaiting Verification"))) -> Verified
A23: WBS-1038 | B23: =IFERROR(INDEX(tblEmployees[Employee Name],MATCH(tblDocuments[[#This Row],[Employee ID]],tblEmployees[Employee ID],0)),"ID not found") -> Vaishnavi Pillai | C23: Address Proof | D23: Submitted | E23: Verified | F23: =IF(tblDocuments[[#This Row],[Submission Status]]<>"Submitted","Not Submitted",IF(tblDocuments[[#This Row],[Verification Status]]="Verified","Verified",IF(tblDocuments[[#This Row],[Verification Status]]="Needs Resubmission","Needs Resubmission","Awaiting Verification"))) -> Verified
A24: WBS-1038 | B24: =IFERROR(INDEX(tblEmployees[Employee Name],MATCH(tblDocuments[[#This Row],[Employee ID]],tblEmployees[Employee ID],0)),"ID not found") -> Vaishnavi Pillai | C24: Education Certificates | D24: Submitted | E24: Not Verified | F24: =IF(tblDocuments[[#This Row],[Submission Status]]<>"Submitted","Not Submitted",IF(tblDocuments[[#This Row],[Verification Status]]="Verified","Verified",IF(tblDocuments[[#This Row],[Verification Status]]="Needs Resubmission","Needs Resubmission","Awaiting Verification"))) -> Awaiting Verification | G24: Sent to verification agency
A25: WBS-1038 | B25: =IFERROR(INDEX(tblEmployees[Employee Name],MATCH(tblDocuments[[#This Row],[Employee ID]],tblEmployees[Employee ID],0)),"ID not found") -> Vaishnavi Pillai | C25: Bank Account Proof | D25: Submitted | E25: Verified | F25: =IF(tblDocuments[[#This Row],[Submission Status]]<>"Submitted","Not Submitted",IF(tblDocuments[[#This Row],[Verification Status]]="Verified","Verified",IF(tblDocuments[[#This Row],[Verification Status]]="Needs Resubmission","Needs Resubmission","Awaiting Verification"))) -> Verified
A26: WBS-1039 | B26: =IFERROR(INDEX(tblEmployees[Employee Name],MATCH(tblDocuments[[#This Row],[Employee ID]],tblEmployees[Employee ID],0)),"ID not found") -> Manoj Nair | C26: Identity Proof | D26: Submitted | E26: Verified | F26: =IF(tblDocuments[[#This Row],[Submission Status]]<>"Submitted","Not Submitted",IF(tblDocuments[[#This Row],[Verification Status]]="Verified","Verified",IF(tblDocuments[[#This Row],[Verification Status]]="Needs Resubmission","Needs Resubmission","Awaiting Verification"))) -> Verified
A27: WBS-1039 | B27: =IFERROR(INDEX(tblEmployees[Employee Name],MATCH(tblDocuments[[#This Row],[Employee ID]],tblEmployees[Employee ID],0)),"ID not found") -> Manoj Nair | C27: Address Proof | D27: Submitted | E27: Verified | F27: =IF(tblDocuments[[#This Row],[Submission Status]]<>"Submitted","Not Submitted",IF(tblDocuments[[#This Row],[Verification Status]]="Verified","Verified",IF(tblDocuments[[#This Row],[Verification Status]]="Needs Resubmission","Needs Resubmission","Awaiting Verification"))) -> Verified
A28: WBS-1039 | B28: =IFERROR(INDEX(tblEmployees[Employee Name],MATCH(tblDocuments[[#This Row],[Employee ID]],tblEmployees[Employee ID],0)),"ID not found") -> Manoj Nair | C28: Education Certificates | D28: Submitted | E28: Verified | F28: =IF(tblDocuments[[#This Row],[Submission Status]]<>"Submitted","Not Submitted",IF(tblDocuments[[#This Row],[Verification Status]]="Verified","Verified",IF(tblDocuments[[#This Row],[Verification Status]]="Needs Resubmission","Needs Resubmission","Awaiting Verification"))) -> Verified
A29: WBS-1039 | B29: =IFERROR(INDEX(tblEmployees[Employee Name],MATCH(tblDocuments[[#This Row],[Employee ID]],tblEmployees[Employee ID],0)),"ID not found") -> Manoj Nair | C29: Bank Account Proof | D29: Submitted | E29: Verified | F29: =IF(tblDocuments[[#This Row],[Submission Status]]<>"Submitted","Not Submitted",IF(tblDocuments[[#This Row],[Verification Status]]="Verified","Verified",IF(tblDocuments[[#This Row],[Verification Status]]="Needs Resubmission","Needs Resubmission","Awaiting Verification"))) -> Verified
A30: WBS-1040 | B30: =IFERROR(INDEX(tblEmployees[Employee Name],MATCH(tblDocuments[[#This Row],[Employee ID]],tblEmployees[Employee ID],0)),"ID not found") -> Amey Joshi | C30: Identity Proof | D30: Submitted | E30: Verified | F30: =IF(tblDocuments[[#This Row],[Submission Status]]<>"Submitted","Not Submitted",IF(tblDocuments[[#This Row],[Verification Status]]="Verified","Verified",IF(tblDocuments[[#This Row],[Verification Status]]="Needs Resubmission","Needs Resubmission","Awaiting Verification"))) -> Verified
A31: WBS-1040 | B31: =IFERROR(INDEX(tblEmployees[Employee Name],MATCH(tblDocuments[[#This Row],[Employee ID]],tblEmployees[Employee ID],0)),"ID not found") -> Amey Joshi | C31: Address Proof | D31: Submitted | E31: Not Verified | F31: =IF(tblDocuments[[#This Row],[Submission Status]]<>"Submitted","Not Submitted",IF(tblDocuments[[#This Row],[Verification Status]]="Verified","Verified",IF(tblDocuments[[#This Row],[Verification Status]]="Needs Resubmission","Needs Resubmission","Awaiting Verification"))) -> Awaiting Verification
A32: WBS-1040 | B32: =IFERROR(INDEX(tblEmployees[Employee Name],MATCH(tblDocuments[[#This Row],[Employee ID]],tblEmployees[Employee ID],0)),"ID not found") -> Amey Joshi | C32: Education Certificates | D32: Submitted | E32: Verified | F32: =IF(tblDocuments[[#This Row],[Submission Status]]<>"Submitted","Not Submitted",IF(tblDocuments[[#This Row],[Verification Status]]="Verified","Verified",IF(tblDocuments[[#This Row],[Verification Status]]="Needs Resubmission","Needs Resubmission","Awaiting Verification"))) -> Verified
A33: WBS-1040 | B33: =IFERROR(INDEX(tblEmployees[Employee Name],MATCH(tblDocuments[[#This Row],[Employee ID]],tblEmployees[Employee ID],0)),"ID not found") -> Amey Joshi | C33: Bank Account Proof | D33: Submitted | E33: Needs Resubmission | F33: =IF(tblDocuments[[#This Row],[Submission Status]]<>"Submitted","Not Submitted",IF(tblDocuments[[#This Row],[Verification Status]]="Verified","Verified",IF(tblDocuments[[#This Row],[Verification Status]]="Needs Resubmission","Needs Resubmission","Awaiting Verification"))) -> Needs Resubmission | G33: Cheque image unclear - re-upload requested
A34: WBS-1041 | B34: =IFERROR(INDEX(tblEmployees[Employee Name],MATCH(tblDocuments[[#This Row],[Employee ID]],tblEmployees[Employee ID],0)),"ID not found") -> Pranav Phadke | C34: Identity Proof | D34: Submitted | E34: Verified | F34: =IF(tblDocuments[[#This Row],[Submission Status]]<>"Submitted","Not Submitted",IF(tblDocuments[[#This Row],[Verification Status]]="Verified","Verified",IF(tblDocuments[[#This Row],[Verification Status]]="Needs Resubmission","Needs Resubmission","Awaiting Verification"))) -> Verified
A35: WBS-1041 | B35: =IFERROR(INDEX(tblEmployees[Employee Name],MATCH(tblDocuments[[#This Row],[Employee ID]],tblEmployees[Employee ID],0)),"ID not found") -> Pranav Phadke | C35: Address Proof | D35: Submitted | E35: Verified | F35: =IF(tblDocuments[[#This Row],[Submission Status]]<>"Submitted","Not Submitted",IF(tblDocuments[[#This Row],[Verification Status]]="Verified","Verified",IF(tblDocuments[[#This Row],[Verification Status]]="Needs Resubmission","Needs Resubmission","Awaiting Verification"))) -> Verified
A36: WBS-1041 | B36: =IFERROR(INDEX(tblEmployees[Employee Name],MATCH(tblDocuments[[#This Row],[Employee ID]],tblEmployees[Employee ID],0)),"ID not found") -> Pranav Phadke | C36: Education Certificates | D36: Submitted | E36: Not Verified | F36: =IF(tblDocuments[[#This Row],[Submission Status]]<>"Submitted","Not Submitted",IF(tblDocuments[[#This Row],[Verification Status]]="Verified","Verified",IF(tblDocuments[[#This Row],[Verification Status]]="Needs Resubmission","Needs Resubmission","Awaiting Verification"))) -> Awaiting Verification
A37: WBS-1041 | B37: =IFERROR(INDEX(tblEmployees[Employee Name],MATCH(tblDocuments[[#This Row],[Employee ID]],tblEmployees[Employee ID],0)),"ID not found") -> Pranav Phadke | C37: Bank Account Proof | D37: Submitted | E37: Verified | F37: =IF(tblDocuments[[#This Row],[Submission Status]]<>"Submitted","Not Submitted",IF(tblDocuments[[#This Row],[Verification Status]]="Verified","Verified",IF(tblDocuments[[#This Row],[Verification Status]]="Needs Resubmission","Needs Resubmission","Awaiting Verification"))) -> Verified
